2023-11-26 19:28:48,157 (root): INFO Starting server

2023-11-26 19:28:50,439 (httpx): INFO HTTP Request: POST https://api.openai.com/v1/chat/completions "HTTP/1.1 403 Forbidden"

2023-11-26 19:28:50,466 (asyncio): ERROR Exception in callback Task.task_wakeup(<Future finished result=None>)
handle: <Handle Task.task_wakeup(<Future finished result=None>)>
Traceback (most recent call last):
  File "/mnt/c/dev/projects/FizzBuzzProjects/myDreamBook/src/api/core/services/gpt_service.py", line 34, in get_dream_interpretation
    dream_response = await self._requester.request(
  File "/mnt/c/dev/projects/FizzBuzzProjects/myDreamBook/src/api/core/infra/requesters/gpt_requester.py", line 25, in request
    response = await self._client.chat.completions.create(
  File "/home/yaroslav/.local/share/virtualenvs/api-M_mDANK4/lib/python3.10/site-packages/openai/resources/chat/completions.py", line 1199, in create
    return await self._post(
  File "/home/yaroslav/.local/share/virtualenvs/api-M_mDANK4/lib/python3.10/site-packages/openai/_base_client.py", line 1482, in post
    return await self.request(cast_to, opts, stream=stream, stream_cls=stream_cls)
  File "/home/yaroslav/.local/share/virtualenvs/api-M_mDANK4/lib/python3.10/site-packages/openai/_base_client.py", line 1283, in request
    return await self._request(
  File "/home/yaroslav/.local/share/virtualenvs/api-M_mDANK4/lib/python3.10/site-packages/openai/_base_client.py", line 1326, in _request
    raise self._make_status_error_from_response(err.response) from None
openai.PermissionDeniedError: <!DOCTYPE html>
<!--[if lt IE 7]> <html class="no-js ie6 oldie" lang="en-US"> <![endif]-->
<!--[if IE 7]>    <html class="no-js ie7 oldie" lang="en-US"> <![endif]-->
<!--[if IE 8]>    <html class="no-js ie8 oldie" lang="en-US"> <![endif]-->
<!--[if gt IE 8]><!--> <html class="no-js" lang="en-US"> <!--<![endif]-->
<head>
<title>Attention Required! | Cloudflare</title>
<meta charset="UTF-8" />
<meta http-equiv="Content-Type" content="text/html; charset=UTF-8" />
<meta http-equiv="X-UA-Compatible" content="IE=Edge" />
<meta name="robots" content="noindex, nofollow" />
<meta name="viewport" content="width=device-width,initial-scale=1" />
<link rel="stylesheet" id="cf_styles-css" href="/cdn-cgi/styles/cf.errors.css" />
<!--[if lt IE 9]><link rel="stylesheet" id='cf_styles-ie-css' href="/cdn-cgi/styles/cf.errors.ie.css" /><![endif]-->
<style>body{margin:0;padding:0}</style>


<!--[if gte IE 10]><!-->
<script>
  if (!navigator.cookieEnabled) {
    window.addEventListener('DOMContentLoaded', function () {
      var cookieEl = document.getElementById('cookie-alert');
      cookieEl.style.display = 'block';
    })
  }
</script>
<!--<![endif]-->


</head>
<body>
  <div id="cf-wrapper">
    <div class="cf-alert cf-alert-error cf-cookie-error" id="cookie-alert" data-translate="enable_cookies">Please enable cookies.</div>
    <div id="cf-error-details" class="cf-error-details-wrapper">
      <div class="cf-wrapper cf-header cf-error-overview">
        <h1 data-translate="block_headline">Sorry, you have been blocked</h1>
        <h2 class="cf-subheadline"><span data-translate="unable_to_access">You are unable to access</span> api.openai.com</h2>
      </div><!-- /.header -->

      <div class="cf-section cf-highlight">
        <div class="cf-wrapper">
          <div class="cf-screenshot-container cf-screenshot-full">
            
              <span class="cf-no-screenshot error"></span>
            
          </div>
        </div>
      </div><!-- /.captcha-container -->

      <div class="cf-section cf-wrapper">
        <div class="cf-columns two">
          <div class="cf-column">
            <h2 data-translate="blocked_why_headline">Why have I been blocked?</h2>

            <p data-translate="blocked_why_detail">This website is using a security service to protect itself from online attacks. The action you just performed triggered the security solution. There are several actions that could trigger this block including submitting a certain word or phrase, a SQL command or malformed data.</p>
          </div>

          <div class="cf-column">
            <h2 data-translate="blocked_resolve_headline">What can I do to resolve this?</h2>

            <p data-translate="blocked_resolve_detail">You can email the site owner to let them know you were blocked. Please include what you were doing when this page came up and the Cloudflare Ray ID found at the bottom of this page.</p>
          </div>
        </div>
      </div><!-- /.section -->

      <div class="cf-error-footer cf-wrapper w-240 lg:w-full py-10 sm:py-4 sm:px-8 mx-auto text-center sm:text-left border-solid border-0 border-t border-gray-300">
  <p class="text-13">
    <span class="cf-footer-item sm:block sm:mb-1">Cloudflare Ray ID: <strong class="font-semibold">82c381c67b851697</strong></span>
    <span class="cf-footer-separator sm:hidden">&bull;</span>
    <span id="cf-footer-item-ip" class="cf-footer-item hidden sm:block sm:mb-1">
      Your IP:
      <button type="button" id="cf-footer-ip-reveal" class="cf-footer-ip-reveal-btn">Click to reveal</button>
      <span class="hidden" id="cf-footer-ip">178.69.53.23</span>
      <span class="cf-footer-separator sm:hidden">&bull;</span>
    </span>
    <span class="cf-footer-item sm:block sm:mb-1"><span>Performance &amp; security by</span> <a rel="noopener noreferrer" href="https://www.cloudflare.com/5xx-error-landing" id="brand_link" target="_blank">Cloudflare</a></span>
    
  </p>
  <script>(function(){function d(){var b=a.getElementById("cf-footer-item-ip"),c=a.getElementById("cf-footer-ip-reveal");b&&"classList"in b&&(b.classList.remove("hidden"),c.addEventListener("click",function(){c.classList.add("hidden");a.getElementById("cf-footer-ip").classList.remove("hidden")}))}var a=document;document.addEventListener&&a.addEventListener("DOMContentLoaded",d)})();</script>
</div><!-- /.error-footer -->


    </div><!-- /#cf-error-details -->
  </div><!-- /#cf-wrapper -->

  <script>
  window._cf_translation = {};
  
  
</script>

</body>
</html>

During handling of the above exception, another exception occurred:

Traceback (most recent call last):
  File "/usr/lib/python3.10/asyncio/events.py", line 80, in _run
    self._context.run(self._callback, *self._args)
RuntimeError: Cannot enter into task <Task pending name='Task-1' coro=<Server.serve() running at /home/yaroslav/.local/share/virtualenvs/api-M_mDANK4/lib/python3.10/site-packages/uvicorn/server.py:81> wait_for=<Future finished result=None> cb=[_run_until_complete_cb() at /usr/lib/python3.10/asyncio/base_events.py:184, WorkerThread.stop()]> while another task <Task pending name='Task-5' coro=<RequestResponseCycle.run_asgi() running at /home/yaroslav/.local/share/virtualenvs/api-M_mDANK4/lib/python3.10/site-packages/uvicorn/protocols/http/h11_impl.py:408> cb=[set.discard()]> is being executed.
